<?xml version="1.0"?>

<robot xmlns:xacro="http://www.ros.org/wiki/xacro" name="bumperbot">

    <!--Link Cha cua tat ca cac link -->
    <link name="base_footprint"/>  

    <!--Base Link-->
    <link name="base_link">
        <visual>
            <origin rpy="0 0 0" xyz="0 0 0"/>
            <geometry>
                <mesh filename="package://bumperbot_description/meshes/base_link.STL"/>
            </geometry>    
        </visual>
    </link>

    <joint name="base_joint" type="fixed">
        <parent link="base_footprint"/>
        <child link="base_link"/>
        <origin rpy="0 0 0" xyz="0 0 0.033" />
    </joint>

    <!--Wheel Right Link-->
    <link name="wheel_right_link">
        <visual>
            <origin rpy="1.57 0 0" xyz="0 0 0"/>  <!-- 1.57 = 90 angle-->
            <geometry>
                <mesh filename="package://bumperbot_description/meshes/wheel_right_link.STL"/>
            </geometry>
        </visual>
    </link>

    <joint name="wheel_right_joint" type="continuous">
        <parent link="base_link"/>
        <child link="wheel_right_link"/>
        <axis xyz="0 1 0"/>
        <origin rpy="0 0 0" xyz="0 -0.07 0"/>
    </joint>

    <!--Wheel Left link-->
    <link name="wheel_left_link">
        <visual>
            <origin rpy="-1.57 0 0" xyz="0 0 0"/>   <!-- -1.57 = 90 angle-->
            <geometry>
                <mesh filename="package://bumperbot_description/meshes/wheel_left_link.STL"/>
            </geometry>
        </visual>
    </link>

    <joint name="wheel_left_joint" type="continuous">
        <parent link="base_link"/>
        <child link="wheel_left_link"/>
        <axis xyz="0 1 0"/>
        <origin rpy="0 0 0" xyz="0 0.07 0"/>
    </joint> 

    <!-- Caster front link-->
    <link name="caster_front_link">
        <visual>
            <origin rpy="0 0 0" xyz="0 0 0"/>
            <geometry>
                <mesh filename="package://bumperbot_description/meshes/caster_front_link.STL"/>
            </geometry>
        </visual>
    </link>

    <joint name="caster_front_joint" type="fixed">
        <parent link="base_link"/>
        <child link="caster_front_link"/>
        <origin rpy="0 0 0" xyz="0.04775 0 -0.0275"/>
    </joint>

        <!-- Caster rear link-->
    <link name="caster_rear_link">
        <visual>
            <origin rpy="0 0 0" xyz="0 0 0"/>
            <geometry>
                <mesh filename="package://bumperbot_description/meshes/caster_rear_link.STL"/>
            </geometry>
        </visual>
    </link>

    <joint name="caster_rear_joint" type="fixed">
        <parent link="base_link"/>
        <child link="caster_rear_link"/>
        <origin rpy="0 0 0" xyz="-0.04775 0 -0.0275"/>
    </joint>


</robot>